Workbook

Sheet Rate Check
A1: Zidane Corporation - Quote PR-217 & PR-228: Brand + Buying Rate Check
A3: Target markup on buying (High): | E3: 0.15 | F3: <- yellow cell change karo, revised rates update ho jayenge
A5: SR# | B5: Item Description | C5: Quoted Brand | D5: Qty | E5: Quoted Rate (PKR) | F5: Correct / Suggested Brand | G5: Buying Low (PKR) | H5: Buying High (PKR) | I5: Margin on High Buy | J5: Status | K5: Revised Rate (PKR) | L5: Quoted Total | M5: Revised Total | N5: Cost Total (High) | O5: Brand Changed? | P5: Status (V/S/N) | Q5: Source / Basis | R5: Note
A6: 1 | B6: STONE CUTTING DISC 4" | C6: Industrial | D6: 30 | E6: 325 | F6: Rhodius | G6: 280 | H6: 280 | I6: =IF(E6=0,0,(E6-H6)/E6) -> 0.13846154 | J6: =IF(E6<G6,"LOSS",IF(E6<H6*1.1,"THIN / RISK",IF(E6>H6*1.8,"OVERPRICED?","OK"))) -> OK | K6: =IF(J6="OVERPRICED?",ROUND(H6*1.35,-1),MAX(E6,ROUND(H6*(1+$E$3),-1))) -> 325 | L6: =D6*E6 -> 9750 | M6: =D6*K6 -> 9750 | N6: =D6*H6 -> 8400 | O6: =IF(ISNUMBER(SEARCH(C6,F6)),"","YES") -> YES | P6: S | Q6: nasirnsons.com Rhodius 4in cutting disc Rs 280; toolshub Permanent 4in 120 | R6: Spec/pack/stock farq - source dekho
A7: 2 | B7: STEEL NAIL 1-1/2" Taiwan | C7: Licota | D7: 2 | E7: 455 | F7: Generic (Taiwan) | G7: 300 | H7: 450 | I7: =IF(E7=0,0,(E7-H7)/E7) -> 0.010989011 | J7: =IF(E7<G7,"LOSS",IF(E7<H7*1.1,"THIN / RISK",IF(E7>H7*1.8,"OVERPRICED?","OK"))) -> THIN / RISK | K7: =IF(J7="OVERPRICED?",ROUND(H7*1.35,-1),MAX(E7,ROUND(H7*(1+$E$3),-1))) -> 520 | L7: =D7*E7 -> 910 | M7: =D7*K7 -> 1040 | N7: =D7*H7 -> 900 | O7: =IF(ISNUMBER(SEARCH(C7,F7)),"","YES") -> YES | P7: N | Q7: Hardware mkt | R7: Online nahi mila - dealer quote chahiye.
A8: 3 | B8: MECHANICAL JACK 5 TON (Japan or Germany) | C8: Licota | D8: 2 | E8: 58500 | F8: Masada (Japan) / Yato | G8: 45000 | H8: 75000 | I8: =IF(E8=0,0,(E8-H8)/E8) -> -0.28205128 | J8: =IF(E8<G8,"LOSS",IF(E8<H8*1.1,"THIN / RISK",IF(E8>H8*1.8,"OVERPRICED?","OK"))) -> THIN / RISK | K8: =IF(J8="OVERPRICED?",ROUND(H8*1.35,-1),MAX(E8,ROUND(H8*(1+$E$3),-1))) -> 86250 | L8: =D8*E8 -> 117000 | M8: =D8*K8 -> 172500 | N8: =D8*H8 -> 150000 | O8: =IF(ISNUMBER(SEARCH(C8,F8)),"","YES") -> YES | P8: N | Q8: Importer quote needed | R8: Online nahi mila - dealer quote chahiye. mech screw jack; alt hydraulic
A9: 4 | B9: DRILL BIT 08 MM (Yato or any Good brand taiwan) | C9: Licota | D9: 50 | E9: 715 | F9: Dormer A002 | G9: 1500 | H9: 2500 | I9: =IF(E9=0,0,(E9-H9)/E9) -> -2.4965035 | J9: =IF(E9<G9,"LOSS",IF(E9<H9*1.1,"THIN / RISK",IF(E9>H9*1.8,"OVERPRICED?","OK"))) -> LOSS | K9: =IF(J9="OVERPRICED?",ROUND(H9*1.35,-1),MAX(E9,ROUND(H9*(1+$E$3),-1))) -> 2880 | L9: =D9*E9 -> 35750 | M9: =D9*K9 -> 144000 | N9: =D9*H9 -> 125000 | O9: =IF(ISNUMBER(SEARCH(C9,F9)),"","YES") -> YES | P9: N | Q9: toolsmart.pk Dormer A002 1-10mm from 900 (8mm exact n/a) | R9: Online nahi mila - dealer quote chahiye. single 8mm (ktools Bosch HSS range 520-5,500
A10: 5 | B10: MECHANICAL JACK 03 TONS (Japan or germany) | C10: Licota | D10: 2 | E10: 41600 | F10: Masada (Japan) / Yato | G10: 32000 | H10: 55000 | I10: =IF(E10=0,0,(E10-H10)/E10) -> -0.32211538 | J10: =IF(E10<G10,"LOSS",IF(E10<H10*1.1,"THIN / RISK",IF(E10>H10*1.8,"OVERPRICED?","OK"))) -> THIN / RISK | K10: =IF(J10="OVERPRICED?",ROUND(H10*1.35,-1),MAX(E10,ROUND(H10*(1+$E$3),-1))) -> 63250 | L10: =D10*E10 -> 83200 | M10: =D10*K10 -> 126500 | N10: =D10*H10 -> 110000 | O10: =IF(ISNUMBER(SEARCH(C10,F10)),"","YES") -> YES | P10: N | Q10: Importer quote needed | R10: Online nahi mila - dealer quote chahiye. mech screw jack; alt hydraulic
A11: 6 | B11: SAFETY HELMET (WHITE) | C11: Industrial | D11: 6 | E11: 1105 | F11: Total | G11: 730 | H11: 730 | I11: =IF(E11=0,0,(E11-H11)/E11) -> 0.33936652 | J11: =IF(E11<G11,"LOSS",IF(E11<H11*1.1,"THIN / RISK",IF(E11>H11*1.8,"OVERPRICED?","OK"))) -> OK | K11: =IF(J11="OVERPRICED?",ROUND(H11*1.35,-1),MAX(E11,ROUND(H11*(1+$E$3),-1))) -> 1105 | L11: =D11*E11 -> 6630 | M11: =D11*K11 -> 6630 | N11: =D11*H11 -> 4380 | O11: =IF(ISNUMBER(SEARCH(C11,F11)),"","YES") -> YES | P11: V | Q11: powerhouseexpress Total TSP2609 730-810 (alt Ingco 1,440)
A12: 7 | B12: SAFETY GOOGLES | C12: Industrial | D12: 24 | E12: 507 | F12: Blue Eagle | G12: 350 | H12: 350 | I12: =IF(E12=0,0,(E12-H12)/E12) -> 0.30966469 | J12: =IF(E12<G12,"LOSS",IF(E12<H12*1.1,"THIN / RISK",IF(E12>H12*1.8,"OVERPRICED?","OK"))) -> OK | K12: =IF(J12="OVERPRICED?",ROUND(H12*1.35,-1),MAX(E12,ROUND(H12*(1+$E$3),-1))) -> 507 | L12: =D12*E12 -> 12168 | M12: =D12*K12 -> 12168 | N12: =D12*H12 -> 8400 | O12: =IF(ISNUMBER(SEARCH(C12,F12)),"","YES") -> YES | P12: V | Q12: mjstraders + hacsons Blue Eagle NP102 350
A13: 8 | B13: 7 DRAWER TOOL TROLLEY | C13: Licota | D13: 3 | E13: 161070 | F13: Licota | G13: 272440 | H13: 272440 | I13: =IF(E13=0,0,(E13-H13)/E13) -> -0.6914385 | J13: =IF(E13<G13,"LOSS",IF(E13<H13*1.1,"THIN / RISK",IF(E13>H13*1.8,"OVERPRICED?","OK"))) -> LOSS | K13: =IF(J13="OVERPRICED?",ROUND(H13*1.35,-1),MAX(E13,ROUND(H13*(1+$E$3),-1))) -> 313310 | L13: =D13*E13 -> 483210 | M13: =D13*K13 -> 939930 | N13: =D13*H13 -> 817320 | O13: =IF(ISNUMBER(SEARCH(C13,F13)),"","YES") | P13: V | Q13: toolsmart.pk LICOTA MADE IN TAIWAN 7 Drawer Cabinet Trolley without tools Rs 272,440 in stock (screenshot Hassan)
A14: 9 | B14: DOUBLE OPEN RING OFFSET WRENCH SET (12PCS) | C14: Licota | D14: 4 | E14: 18200 | F14: Licota | G14: 29600 | H14: 29600 | I14: =IF(E14=0,0,(E14-H14)/E14) -> -0.62637363 | J14: =IF(E14<G14,"LOSS",IF(E14<H14*1.1,"THIN / RISK",IF(E14>H14*1.8,"OVERPRICED?","OK"))) -> LOSS | K14: =IF(J14="OVERPRICED?",ROUND(H14*1.35,-1),MAX(E14,ROUND(H14*(1+$E$3),-1))) -> 34040 | L14: =D14*E14 -> 72800 | M14: =D14*K14 -> 136160 | N14: =D14*H14 -> 118400 | O14: =IF(ISNUMBER(SEARCH(C14,F14)),"","YES") | P14: S | Q14: toolsmart.pk Licota offset ring singles 8x10 1,230 / 14x15 2,060 / 24x26 3,420 / 30x32 4,240 -> 12pc 6-32 sum ~29,600 | R14: Spec/pack/stock farq - source dekho
A15: 10 | B15: DOUBLE OPEN END WRENCH 6 TO 32 (12 PCS SET) | C15: Licota | D15: 4 | E15: 15600 | F15: Harden | G15: 12630 | H15: 12630 | I15: =IF(E15=0,0,(E15-H15)/E15) -> 0.19038462 | J15: =IF(E15<G15,"LOSS",IF(E15<H15*1.1,"THIN / RISK",IF(E15>H15*1.8,"OVERPRICED?","OK"))) -> OK | K15: =IF(J15="OVERPRICED?",ROUND(H15*1.35,-1),MAX(E15,ROUND(H15*(1+$E$3),-1))) -> 15600 | L15: =D15*E15 -> 62400 | M15: =D15*K15 -> 62400 | N15: =D15*H15 -> 50520 | O15: =IF(ISNUMBER(SEARCH(C15,F15)),"","YES") -> YES | P15: V | Q15: toolsmart.pk Harden double open-end spanner 6-32mm 12pc Rs 12,630 (alt Ingco HKSPA2142 ingcotool 9,899)
A16: 11 | B16: DOUBLE OPEN END WRENCH 36X41 | C16: Licota | D16: 3 | E16: 3640 | F16: Licota | G16: 7430 | H16: 7430 | I16: =IF(E16=0,0,(E16-H16)/E16) -> -1.0412088 | J16: =IF(E16<G16,"LOSS",IF(E16<H16*1.1,"THIN / RISK",IF(E16>H16*1.8,"OVERPRICED?","OK"))) -> LOSS | K16: =IF(J16="OVERPRICED?",ROUND(H16*1.35,-1),MAX(E16,ROUND(H16*(1+$E$3),-1))) -> 8540 | L16: =D16*E16 -> 10920 | M16: =D16*K16 -> 25620 | N16: =D16*H16 -> 22290 | O16: =IF(ISNUMBER(SEARCH(C16,F16)),"","YES") | P16: V | Q16: toolsmart.pk Licota double open end 36x41 Rs 7,430
A17: 12 | B17: DOUBLE OPEN END WRENCH 41X46 | C17: Licota | D17: 3 | E17: 4550 | F17: Licota | G17: 12310 | H17: 12310 | I17: =IF(E17=0,0,(E17-H17)/E17) -> -1.7054945 | J17: =IF(E17<G17,"LOSS",IF(E17<H17*1.1,"THIN / RISK",IF(E17>H17*1.8,"OVERPRICED?","OK"))) -> LOSS | K17: =IF(J17="OVERPRICED?",ROUND(H17*1.35,-1),MAX(E17,ROUND(H17*(1+$E$3),-1))) -> 14160 | L17: =D17*E17 -> 13650 | M17: =D17*K17 -> 42480 | N17: =D17*H17 -> 36930 | O17: =IF(ISNUMBER(SEARCH(C17,F17)),"","YES") | P17: V | Q17: toolsmart.pk Licota double open end 41x46 Rs 12,310
A18: 13 | B18: COMBINATION WRENCH 8 TO 32 (14 PCS SET) | C18: Licota | D18: 4 | E18: 22100 | F18: Tolsen | G18: 11780 | H18: 11780 | I18: =IF(E18=0,0,(E18-H18)/E18) -> 0.46696833 | J18: =IF(E18<G18,"LOSS",IF(E18<H18*1.1,"THIN / RISK",IF(E18>H18*1.8,"OVERPRICED?","OK"))) -> OVERPRICED? | K18: =IF(J18="OVERPRICED?",ROUND(H18*1.35,-1),MAX(E18,ROUND(H18*(1+$E$3),-1))) -> 15900 | L18: =D18*E18 -> 88400 | M18: =D18*K18 -> 63600 | N18: =D18*H18 -> 47120 | O18: =IF(ISNUMBER(SEARCH(C18,F18)),"","YES") -> YES | P18: V | Q18: imsons.com.pk Tolsen 15889 combination spanner 6-32mm 14pc Rs 11,780; toolexpert.pk 7,500
A19: 14 | B19: SOCKET SET (113PCS) 1/4" & 1/2" | C19: Licota | D19: 4 | E19: 75400 | F19: Licota | G19: 67130 | H19: 67130 | I19: =IF(E19=0,0,(E19-H19)/E19) -> 0.1096817 | J19: =IF(E19<G19,"LOSS",IF(E19<H19*1.1,"THIN / RISK",IF(E19>H19*1.8,"OVERPRICED?","OK"))) -> OK | K19: =IF(J19="OVERPRICED?",ROUND(H19*1.35,-1),MAX(E19,ROUND(H19*(1+$E$3),-1))) -> 77200 | L19: =D19*E19 -> 301600 | M19: =D19*K19 -> 308800 | N19: =D19*H19 -> 268520 | O19: =IF(ISNUMBER(SEARCH(C19,F19)),"","YES") | P19: V | Q19: toolsmart Licota 120pc 56,890-67,130
A20: 15 | B20: PIN PUNCH SET (06PCS SET) | C20: Licota | D20: 4 | E20: 5850 | F20: Licota | G20: 5460 | H20: 5460 | I20: =IF(E20=0,0,(E20-H20)/E20) -> 0.066666667 | J20: =IF(E20<G20,"LOSS",IF(E20<H20*1.1,"THIN / RISK",IF(E20>H20*1.8,"OVERPRICED?","OK"))) -> THIN / RISK | K20: =IF(J20="OVERPRICED?",ROUND(H20*1.35,-1),MAX(E20,ROUND(H20*(1+$E$3),-1))) -> 6280 | L20: =D20*E20 -> 23400 | M20: =D20*K20 -> 25120 | N20: =D20*H20 -> 21840 | O20: =IF(ISNUMBER(SEARCH(C20,F20)),"","YES") | P20: V | Q20: toolsmart.pk Licota 6pc pin punch 5,460; ktools.pk 6,000 (oos)
A21: 16 | B21: HOLLOW PUNCH (3MM-25MM) (15PCS SET) | C21: Licota | D21: 4 | E21: 8450 | F21: Harden | G21: 4699 | H21: 4699 | I21: =IF(E21=0,0,(E21-H21)/E21) -> 0.44390533 | J21: =IF(E21<G21,"LOSS",IF(E21<H21*1.1,"THIN / RISK",IF(E21>H21*1.8,"OVERPRICED?","OK"))) -> OK | K21: =IF(J21="OVERPRICED?",ROUND(H21*1.35,-1),MAX(E21,ROUND(H21*(1+$E$3),-1))) -> 8450 | L21: =D21*E21 -> 33800 | M21: =D21*K21 -> 33800 | N21: =D21*H21 -> 18796 | O21: =IF(ISNUMBER(SEARCH(C21,F21)),"","YES") -> YES | P21: S | Q21: Harden 12pc hollow punch 3-16mm 610848: toolsmart 4,140; ingcotool 4,199-4,699; toolshop 4,399 | R21: Spec/pack/stock farq - source dekho
A22: 17 | B22: LONG TYPE HEX KEY WRENCH SET 09 PCS | C22: Licota | D22: 4 | E22: 2548 | F22: Licota | G22: 4400 | H22: 4400 | I22: =IF(E22=0,0,(E22-H22)/E22) -> -0.72684458 | J22: =IF(E22<G22,"LOSS",IF(E22<H22*1.1,"THIN / RISK",IF(E22>H22*1.8,"OVERPRICED?","OK"))) -> LOSS | K22: =IF(J22="OVERPRICED?",ROUND(H22*1.35,-1),MAX(E22,ROUND(H22*(1+$E$3),-1))) -> 5060 | L22: =D22*E22 -> 10192 | M22: =D22*K22 -> 20240 | N22: =D22*H22 -> 17600 | O22: =IF(ISNUMBER(SEARCH(C22,F22)),"","YES") | P22: V | Q22: toolsmart Licota 9pc long hex 4,400
A23: 18 | B23: SHORT TYPE HEX KEY WRENCH SET (09PCS) | C23: Licota | D23: 4 | E23: 1846 | F23: Licota | G23: 3540 | H23: 3540 | I23: =IF(E23=0,0,(E23-H23)/E23) -> -0.9176598 | J23: =IF(E23<G23,"LOSS",IF(E23<H23*1.1,"THIN / RISK",IF(E23>H23*1.8,"OVERPRICED?","OK"))) -> LOSS | K23: =IF(J23="OVERPRICED?",ROUND(H23*1.35,-1),MAX(E23,ROUND(H23*(1+$E$3),-1))) -> 4070 | L23: =D23*E23 -> 7384 | M23: =D23*K23 -> 16280 | N23: =D23*H23 -> 14160 | O23: =IF(ISNUMBER(SEARCH(C23,F23)),"","YES") | P23: V | Q23: toolsmart.pk Licota 9pc short type hex key set 1.5-10mm Rs 3,540
A24: 19 | B24: LONG TYPE HEX WRENCH SET 09 PCS | C24: Licota | D24: 4 | E24: 2548 | F24: Licota | G24: 4400 | H24: 4400 | I24: =IF(E24=0,0,(E24-H24)/E24) -> -0.72684458 | J24: =IF(E24<G24,"LOSS",IF(E24<H24*1.1,"THIN / RISK",IF(E24>H24*1.8,"OVERPRICED?","OK"))) -> LOSS | K24: =IF(J24="OVERPRICED?",ROUND(H24*1.35,-1),MAX(E24,ROUND(H24*(1+$E$3),-1))) -> 5060 | L24: =D24*E24 -> 10192 | M24: =D24*K24 -> 20240 | N24: =D24*H24 -> 17600 | O24: =IF(ISNUMBER(SEARCH(C24,F24)),"","YES") | P24: V | Q24: same as 17
A25: 20 | B25: ALLEN HEX KEY 12MM | C25: Licota | D25: 3 | E25: 910 | F25: Licota | G25: 1050 | H25: 1250 | I25: =IF(E25=0,0,(E25-H25)/E25) -> -0.37362637 | J25: =IF(E25<G25,"LOSS",IF(E25<H25*1.1,"THIN / RISK",IF(E25>H25*1.8,"OVERPRICED?","OK"))) -> LOSS | K25: =IF(J25="OVERPRICED?",ROUND(H25*1.35,-1),MAX(E25,ROUND(H25*(1+$E$3),-1))) -> 1440 | L25: =D25*E25 -> 2730 | M25: =D25*K25 -> 4320 | N25: =D25*H25 -> 3750 | O25: =IF(ISNUMBER(SEARCH(C25,F25)),"","YES") | P25: N | Q25: goldentools.ae Licota 12mm hex AED 250/20pc (12.5 ea) x90; Licota PK/UAE ratio ~90 (calibrated: locking plier 10in 4,000/AED42, 143pc 104,750/AED1,200, pin punch 5,460/AED48, hex 9pc 4,400/AED45) | R25: Online nahi mila - dealer quote chahiye.
A26: 21 | B26: ALLEN (HEX) KEY 14MM | C26: Licota | D26: 3 | E26: 1170 | F26: Licota | G26: 1350 | H26: 1600 | I26: =IF(E26=0,0,(E26-H26)/E26) -> -0.36752137 | J26: =IF(E26<G26,"LOSS",IF(E26<H26*1.1,"THIN / RISK",IF(E26>H26*1.8,"OVERPRICED?","OK"))) -> LOSS | K26: =IF(J26="OVERPRICED?",ROUND(H26*1.35,-1),MAX(E26,ROUND(H26*(1+$E$3),-1))) -> 1840 | L26: =D26*E26 -> 3510 | M26: =D26*K26 -> 5520 | N26: =D26*H26 -> 4800 | O26: =IF(ISNUMBER(SEARCH(C26,F26)),"","YES") | P26: N | Q26: goldentools.ae Licota hex 12mm scaled to 14mm x90 | R26: Online nahi mila - dealer quote chahiye.
A27: 22 | B27: ALLEN (HEX) KEY 16MM | C27: Licota | D27: 3 | E27: 1430 | F27: Licota | G27: 1700 | H27: 2000 | I27: =IF(E27=0,0,(E27-H27)/E27) -> -0.3986014 | J27: =IF(E27<G27,"LOSS",IF(E27<H27*1.1,"THIN / RISK",IF(E27>H27*1.8,"OVERPRICED?","OK"))) -> LOSS | K27: =IF(J27="OVERPRICED?",ROUND(H27*1.35,-1),MAX(E27,ROUND(H27*(1+$E$3),-1))) -> 2300 | L27: =D27*E27 -> 4290 | M27: =D27*K27 -> 6900 | N27: =D27*H27 -> 6000 | O27: =IF(ISNUMBER(SEARCH(C27,F27)),"","YES") | P27: N | Q27: goldentools.ae Licota hex 12mm scaled to 16mm x90 | R27: Online nahi mila - dealer quote chahiye.
A28: 23 | B28: CIRCLIP PLIER INTERNAL STRAIGHT 175MM | C28: Licota | D28: 4 | E28: 4940 | F28: Licota | G28: 3438 | H28: 3438 | I28: =IF(E28=0,0,(E28-H28)/E28) -> 0.30404858 | J28: =IF(E28<G28,"LOSS",IF(E28<H28*1.1,"THIN / RISK",IF(E28>H28*1.8,"OVERPRICED?","OK"))) -> OK | K28: =IF(J28="OVERPRICED?",ROUND(H28*1.35,-1),MAX(E28,ROUND(H28*(1+$E$3),-1))) -> 4940 | L28: =D28*E28 -> 19760 | M28: =D28*K28 -> 19760 | N28: =D28*H28 -> 13752 | O28: =IF(ISNUMBER(SEARCH(C28,F28)),"","YES") | P28: V | Q28: toolsmart.pk Licota 4pc snap ring set 175mm Rs 13,750 (=3,438/pc)
A29: 24 | B29: CIRCLIP PLIER INTERNAL BENT 175MM | C29: Licota | D29: 4 | E29: 4940 | F29: Licota | G29: 3438 | H29: 3438 | I29: =IF(E29=0,0,(E29-H29)/E29) -> 0.30404858 | J29: =IF(E29<G29,"LOSS",IF(E29<H29*1.1,"THIN / RISK",IF(E29>H29*1.8,"OVERPRICED?","OK"))) -> OK | K29: =IF(J29="OVERPRICED?",ROUND(H29*1.35,-1),MAX(E29,ROUND(H29*(1+$E$3),-1))) -> 4940 | L29: =D29*E29 -> 19760 | M29: =D29*K29 -> 19760 | N29: =D29*H29 -> 13752 | O29: =IF(ISNUMBER(SEARCH(C29,F29)),"","YES") | P29: V | Q29: toolsmart.pk Licota 4pc snap ring set 175mm Rs 13,750 (=3,438/pc)
A30: 25 | B30: CIRCLIP PLIER EXTERNAL STRAIGHT 175MM | C30: Licota | D30: 4 | E30: 4940 | F30: Licota | G30: 3438 | H30: 3438 | I30: =IF(E30=0,0,(E30-H30)/E30) -> 0.30404858 | J30: =IF(E30<G30,"LOSS",IF(E30<H30*1.1,"THIN / RISK",IF(E30>H30*1.8,"OVERPRICED?","OK"))) -> OK | K30: =IF(J30="OVERPRICED?",ROUND(H30*1.35,-1),MAX(E30,ROUND(H30*(1+$E$3),-1))) -> 4940 | L30: =D30*E30 -> 19760 | M30: =D30*K30 -> 19760 | N30: =D30*H30 -> 13752 | O30: =IF(ISNUMBER(SEARCH(C30,F30)),"","YES") | P30: V | Q30: toolsmart.pk Licota 4pc snap ring set 175mm Rs 13,750 (=3,438/pc)
A31: 26 | B31: CIRCLIP PLIER EXTERNAL BENT 175MM | C31: Licota | D31: 4 | E31: 4940 | F31: Licota | G31: 3438 | H31: 3438 | I31: =IF(E31=0,0,(E31-H31)/E31) -> 0.30404858 | J31: =IF(E31<G31,"LOSS",IF(E31<H31*1.1,"THIN / RISK",IF(E31>H31*1.8,"OVERPRICED?","OK"))) -> OK | K31: =IF(J31="OVERPRICED?",ROUND(H31*1.35,-1),MAX(E31,ROUND(H31*(1+$E$3),-1))) -> 4940 | L31: =D31*E31 -> 19760 | M31: =D31*K31 -> 19760 | N31: =D31*H31 -> 13752 | O31: =IF(ISNUMBER(SEARCH(C31,F31)),"","YES") | P31: V | Q31: toolsmart.pk Licota 4pc snap ring set 175mm Rs 13,750 (=3,438/pc)
A32: 27 | B32: CIRCLIP PLIER INTERNAL STRAIGHT 230MM | C32: Licota | D32: 4 | E32: 6760 | F32: Licota | G32: 4300 | H32: 4800 | I32: =IF(E32=0,0,(E32-H32)/E32) -> 0.28994083 | J32: =IF(E32<G32,"LOSS",IF(E32<H32*1.1,"THIN / RISK",IF(E32>H32*1.8,"OVERPRICED?","OK"))) -> OK | K32: =IF(J32="OVERPRICED?",ROUND(H32*1.35,-1),MAX(E32,ROUND(H32*(1+$E$3),-1))) -> 6760 | L32: =D32*E32 -> 27040 | M32: =D32*K32 -> 27040 | N32: =D32*H32 -> 19200 | O32: =IF(ISNUMBER(SEARCH(C32,F32)),"","YES") | P32: N | Q32: goldentools.ae Licota snap ring set 4pc 175mm AED 212.5; toolsmart.pk same set 13,750 (3,438/pc) -> 230mm +30% | R32: Online nahi mila - dealer quote chahiye. 230mm circlip
A33: 28 | B33: CIRCLIP PLIER EXTERNAL STRAIGHT 230MM | C33: Licota | D33: 3 | E33: 6760 | F33: Licota | G33: 4300 | H33: 4800 | I33: =IF(E33=0,0,(E33-H33)/E33) -> 0.28994083 | J33: =IF(E33<G33,"LOSS",IF(E33<H33*1.1,"THIN / RISK",IF(E33>H33*1.8,"OVERPRICED?","OK"))) -> OK | K33: =IF(J33="OVERPRICED?",ROUND(H33*1.35,-1),MAX(E33,ROUND(H33*(1+$E$3),-1))) -> 6760 | L33: =D33*E33 -> 20280 | M33: =D33*K33 -> 20280 | N33: =D33*H33 -> 14400 | O33: =IF(ISNUMBER(SEARCH(C33,F33)),"","YES") | P33: N | Q33: goldentools.ae Licota snap ring set 4pc 175mm AED 212.5; toolsmart.pk same set 13,750 (3,438/pc) -> 230mm +30% | R33: Online nahi mila - dealer quote chahiye. 230mm circlip
A34: 30 | B34: CHISEL SET (05 PCS SET) | C34: Licota | D34: 4 | E34: 6136 | F34: Licota | G34: 4720 | H34: 4720 | I34: =IF(E34=0,0,(E34-H34)/E34) -> 0.23076923 | J34: =IF(E34<G34,"LOSS",IF(E34<H34*1.1,"THIN / RISK",IF(E34>H34*1.8,"OVERPRICED?","OK"))) -> OK | K34: =IF(J34="OVERPRICED?",ROUND(H34*1.35,-1),MAX(E34,ROUND(H34*(1+$E$3),-1))) -> 6136 | L34: =D34*E34 -> 24544 | M34: =D34*K34 -> 24544 | N34: =D34*H34 -> 18880 | O34: =IF(ISNUMBER(SEARCH(C34,F34)),"","YES") | P34: V | Q34: toolsmart Licota 5pc punch chisel 4,000-4,720
A35: 31 | B35: PIPE WRENCH SIZE 10" | C35: Licota | D35: 3 | E35: 2210 | F35: Total | G35: 1700 | H35: 1700 | I35: =IF(E35=0,0,(E35-H35)/E35) -> 0.23076923 | J35: =IF(E35<G35,"LOSS",IF(E35<H35*1.1,"THIN / RISK",IF(E35>H35*1.8,"OVERPRICED?","OK"))) -> OK | K35: =IF(J35="OVERPRICED?",ROUND(H35*1.35,-1),MAX(E35,ROUND(H35*(1+$E$3),-1))) -> 2210 | L35: =D35*E35 -> 6630 | M35: =D35*K35 -> 6630 | N35: =D35*H35 -> 5100 | O35: =IF(ISNUMBER(SEARCH(C35,F35)),"","YES") -> YES | P35: V | Q35: toolsmart.pk Total pipe wrench 10in Rs 1,700; totaltool.pk 1,400
A36: 32 | B36: PIPE WRENCH SIZE 12" | C36: Licota | D36: 3 | E36: 2886 | F36: Harden | G36: 2850 | H36: 2850 | I36: =IF(E36=0,0,(E36-H36)/E36) -> 0.012474012 | J36: =IF(E36<G36,"LOSS",IF(E36<H36*1.1,"THIN / RISK",IF(E36>H36*1.8,"OVERPRICED?","OK"))) -> THIN / RISK | K36: =IF(J36="OVERPRICED?",ROUND(H36*1.35,-1),MAX(E36,ROUND(H36*(1+$E$3),-1))) -> 3280 | L36: =D36*E36 -> 8658 | M36: =D36*K36 -> 9840 | N36: =D36*H36 -> 8550 | O36: =IF(ISNUMBER(SEARCH(C36,F36)),"","YES") -> YES | P36: V | Q36: toolsmart.pk Harden heavy duty pipe wrench 12in Rs 2,850
A37: 33 | B37: PIPE WRENCH SIZE 18" | C37: Licota | D37: 3 | E37: 5902 | F37: Licota | G37: 9620 | H37: 9620 | I37: =IF(E37=0,0,(E37-H37)/E37) -> -0.62995595 | J37: =IF(E37<G37,"LOSS",IF(E37<H37*1.1,"THIN / RISK",IF(E37>H37*1.8,"OVERPRICED?","OK"))) -> LOSS | K37: =IF(J37="OVERPRICED?",ROUND(H37*1.35,-1),MAX(E37,ROUND(H37*(1+$E$3),-1))) -> 11060 | L37: =D37*E37 -> 17706 | M37: =D37*K37 -> 33180 | N37: =D37*H37 -> 28860 | O37: =IF(ISNUMBER(SEARCH(C37,F37)),"","YES") | P37: V | Q37: toolsmart Licota 18in pipe wrench 9,620
A38: 34 | B38: PIPE WRENCH SIZE 24" | C38: Licota | D38: 2 | E38: 6120 | F38: Harden | G38: 6560 | H38: 6560 | I38: =IF(E38=0,0,(E38-H38)/E38) -> -0.071895425 | J38: =IF(E38<G38,"LOSS",IF(E38<H38*1.1,"THIN / RISK",IF(E38>H38*1.8,"OVERPRICED?","OK"))) -> LOSS | K38: =IF(J38="OVERPRICED?",ROUND(H38*1.35,-1),MAX(E38,ROUND(H38*(1+$E$3),-1))) -> 7540 | L38: =D38*E38 -> 12240 | M38: =D38*K38 -> 15080 | N38: =D38*H38 -> 13120 | O38: =IF(ISNUMBER(SEARCH(C38,F38)),"","YES") -> YES | P38: V | Q38: toolsmart.pk Harden pipe wrench 24in Rs 6,560
A39: 35 | B39: PIPE WRENCH SIZE 36" | C39: Licota | D39: 2 | E39: 12870 | F39: Total | G39: 7900 | H39: 7900 | I39: =IF(E39=0,0,(E39-H39)/E39) -> 0.38616939 | J39: =IF(E39<G39,"LOSS",IF(E39<H39*1.1,"THIN / RISK",IF(E39>H39*1.8,"OVERPRICED?","OK"))) -> OK | K39: =IF(J39="OVERPRICED?",ROUND(H39*1.35,-1),MAX(E39,ROUND(H39*(1+$E$3),-1))) -> 12870 | L39: =D39*E39 -> 25740 | M39: =D39*K39 -> 25740 | N39: =D39*H39 -> 15800 | O39: =IF(ISNUMBER(SEARCH(C39,F39)),"","YES") -> YES | P39: V | Q39: totaltool.pk Total pipe wrench 36in THT171366 Rs 7,900 (alt Wiseup toolshub 6,300)
A40: 36 | B40: SLEDGE HAMMER 1 LBS WITH FIBREGLASS HANDLE | C40: Licota | D40: 3 | E40: 1950 | F40: Total | G40: 2000 | H40: 2000 | I40: =IF(E40=0,0,(E40-H40)/E40) -> -0.025641026 | J40: =IF(E40<G40,"LOSS",IF(E40<H40*1.1,"THIN / RISK",IF(E40>H40*1.8,"OVERPRICED?","OK"))) -> LOSS | K40: =IF(J40="OVERPRICED?",ROUND(H40*1.35,-1),MAX(E40,ROUND(H40*(1+$E$3),-1))) -> 2300 | L40: =D40*E40 -> 5850 | M40: =D40*K40 -> 6900 | N40: =D40*H40 -> 6000 | O40: =IF(ISNUMBER(SEARCH(C40,F40)),"","YES") -> YES | P40: S | Q40: toolsmart.pk Total sledge 2lb THT79026 Rs 2,000; purchaser 1,820 (1lb nahi mila) | R40: Spec/pack/stock farq - source dekho
A41: 37 | B41: SLEDGE HAMMER 3 LBS WITH FIBREGLASS HANDLE | C41: Licota | D41: 3 | E41: 4550 | F41: Harden | G41: 3380 | H41: 3380 | I41: =IF(E41=0,0,(E41-H41)/E41) -> 0.25714286 | J41: =IF(E41<G41,"LOSS",IF(E41<H41*1.1,"THIN / RISK",IF(E41>H41*1.8,"OVERPRICED?","OK"))) -> OK | K41: =IF(J41="OVERPRICED?",ROUND(H41*1.35,-1),MAX(E41,ROUND(H41*(1+$E$3),-1))) -> 4550 | L41: =D41*E41 -> 13650 | M41: =D41*K41 -> 13650 | N41: =D41*H41 -> 10140 | O41: =IF(ISNUMBER(SEARCH(C41,F41)),"","YES") -> YES | P41: V | Q41: toolsmart.pk Harden 3lb sledge fibreglass 590323 Rs 3,380
A42: 38 | B42: SOFT FACE DEAD BLOW HAMMER 50MM | C42: Licota | D42: 3 | E42: 6240 | F42: Harden | G42: 2450 | H42: 2450 | I42: =IF(E42=0,0,(E42-H42)/E42) -> 0.60737179 | J42: =IF(E42<G42,"LOSS",IF(E42<H42*1.1,"THIN / RISK",IF(E42>H42*1.8,"OVERPRICED?","OK"))) -> OVERPRICED? | K42: =IF(J42="OVERPRICED?",ROUND(H42*1.35,-1),MAX(E42,ROUND(H42*(1+$E$3),-1))) -> 3310 | L42: =D42*E42 -> 18720 | M42: =D42*K42 -> 9930 | N42: =D42*H42 -> 7350 | O42: =IF(ISNUMBER(SEARCH(C42,F42)),"","YES") -> YES | P42: V | Q42: pakistanpowertools.com Harden dead blow mallet 590445 Rs 1,987-2,450
...

Sheet Summary
A1: Summary - Quote PR-217 & PR-228
A3: Total line items | B3: =COUNTA('Rate Check'!A6:A227) -> 222
A4: LOSS items (quoted < lowest buying) | B4: =COUNTIF('Rate Check'!J6:J227,"LOSS") -> 77
A5: THIN / RISK items (<10% over high buying) | B5: =COUNTIF('Rate Check'!J6:J227,"THIN / RISK") -> 45
A6: OK items | B6: =COUNTIF('Rate Check'!J6:J227,"OK") -> 78
A7: OVERPRICED? items (>80% over high buying) | B7: =COUNTIF('Rate Check'!J6:J227,"OVERPRICED?") -> 22
A8: Items where brand must change | B8: =COUNTIF('Rate Check'!O6:O227,"YES") -> 158
A10: Quoted total (PKR) | B10: ='Rate Check'!L228 -> 12209508
A11: Estimated cost at HIGH buying (PKR) | B11: ='Rate Check'!N228 -> 11614372
A12: Gross margin on quote (PKR) | B12: =B10-B11 -> 595136
A13: Gross margin % | B13: =IF(B10=0,0,B12/B10) -> 0.048743651
A14: Loss on LOSS/THIN lines (PKR, at high buying) | B14: =SUMPRODUCT(('Rate Check'!E6:E227<'Rate Check'!H6:H227)*('Rate Check'!H6:H227-'Rate Check'!E6:E227)*'Rate Check'!D6:D227) -> 2412436
A16: Revised quote total (PKR) | B16: ='Rate Check'!M228 -> 14661411
A17: Revised margin % | B17: =IF(B16=0,0,(B16-B11)/B16) -> 0.20782713
A19: V items (exact online listing) | B19: =COUNTIF('Rate Check'!P6:P227,"V") -> 75
A20: S items (listed, spec/pack farq) | B20: =COUNTIF('Rate Check'!P6:P227,"S") -> 25
A21: N items (online nahi - dealer quote) | B21: =COUNTIF('Rate Check'!P6:P227,"N") -> 122

Sheet Sources
A1: Sources (checked Oct 2026 - prices change, confirm before PO)
A3: toolsmart.pk - Licota collection | B3: https://www.toolsmart.pk/collections/licota
A4: toolsmart.pk - Licota 18in pipe wrench Rs 9,620 | B4: https://www.toolsmart.pk/products/licota-18-heavy-duty-ridgid-type-pipe-wrench-cr-mo
A5: toolsmart.pk - Licota 9pc extra long hex | B5: https://www.toolsmart.pk/products/licota-9pcs-extra-long-type-hex-key-set
A6: toolsmart.pk - Licota 120pc socket set | B6: https://www.toolsmart.pk/products/licota-120pcs-1-4-3-8-1-2-dr-socket-set
A7: toolsmart.pk - grease guns (Licota 400cc Rs 7,760) | B7: https://www.toolsmart.pk/collections/all-tools/grease-gun
A8: kamadi.pk - Bosch GDS 18V-1000 | B8: https://kamadi.pk/products/gds-18v-1000-bosch-cordless-impact-wrench-650n-m-18v
A9: kamadi.pk - Bosch GDX 180-Li | B9: https://kamadi.pk/products/gdx-180-li-bosch-cordless-impact-driver-wrench-180n-m-18v
A10: kamadi.pk - Bosch GWS 2200-230 H | B10: https://kamadi.pk/products/bosch-gws-2200-230-h-angle-grinder
A11: kamadi.pk - Insize 1205-300S | B11: https://kamadi.pk/products/insize-1205-300s-vernier-caliper-0-300mm
A12: kamadi.pk - Insize 1108-300 | B12: https://kamadi.pk/products/1108-300-insize-digital-4-way-vernier-caliper-0-300mm
A13: kamadi.pk - Insize 3109-25A micrometer | B13: https://kamadi.pk/products/insize-3109-25a-digital-outside-micrometer-0-25mm
A14: ktools.pk - Bosch GDS 18V-1000 solo | B14: https://www.ktools.pk/products/bosch-gds-18v-1000-cordless-impact-wrench
... A32: goldpeaktools.com.ph - Licota AWX-2603GN 7-drawer (ref) | B32: https://shop.goldpeaktools.com.ph/products/licota-awx-2603gn-tool-cabinet-carriage-7-drawers
